Workbook

Sheet RadGridExport - 2026-09-18T0901
A1: Kimlik | B1: Ad | C1: Öğrenci | D1: Eğitim Programı | E1: Sınıf | F1: Şube
A2: No | B2: Soyad | C2: Eğitim Türü | D2: Dal Adı | E2: No | F2: Adı
A4: 51274185610 | B4: Umut KAYA | C4: Mesleki Eğitim + Diploma | D4: Asansör Sistemleri | E4: 9 | F4: D | G4: =RIGHT(A4,5) -> 85610 | H4: =B4 -> Umut KAYA | I4: =CONCATENATE(E4,F4," ",D4) -> 9D Asansör Sistemleri | J4: =LEFT(I4,3) -> 9D
A5: 17897587170 | B5: Ahmet Emin KAYA | C5: Mesleki Eğitim + Diploma | D5: Aşçılık | E5: 9 | F5: G1 | G5: =RIGHT(A5,5) -> 87170 | H5: =B5 -> Ahmet Emin KAYA | I5: =CONCATENATE(E5,F5," ",D5) -> 9G1 Aşçılık | J5: =LEFT(I5,3) -> 9G1
A6: 99762019092 | B6: Bahruz ALIZADA | C6: Mesleki Eğitim + Diploma | D6: Aşçılık | E6: 9 | F6: G1 | G6: =RIGHT(A6,5) -> 19092 | H6: =B6 -> Bahruz ALIZADA | I6: =CONCATENATE(E6,F6," ",D6) -> 9G1 Aşçılık | J6: =LEFT(I6,3) -> 9G1
A7: 63934052934 | B7: Elifnur ŞENGÜL | C7: Mesleki Eğitim + Diploma | D7: Aşçılık | E7: 9 | F7: G1 | G7: =RIGHT(A7,5) -> 52934 | H7: =B7 -> Elifnur ŞENGÜL | I7: =CONCATENATE(E7,F7," ",D7) -> 9G1 Aşçılık | J7: =LEFT(I7,3) -> 9G1
A8: 48226575728 | B8: Gül Deniz BİLECEN | C8: Mesleki Eğitim + Diploma | D8: Aşçılık | E8: 9 | F8: G1 | G8: =RIGHT(A8,5) -> 75728 | H8: =B8 -> Gül Deniz BİLECEN | I8: =CONCATENATE(E8,F8," ",D8) -> 9G1 Aşçılık | J8: =LEFT(I8,3) -> 9G1
A9: 26270044094 | B9: Levent Eymen BAŞKÖYLÜ | C9: Mesleki Eğitim + Diploma | D9: Aşçılık | E9: 9 | F9: G1 | G9: =RIGHT(A9,5) -> 44094 | H9: =B9 -> Levent Eymen BAŞKÖYLÜ | I9: =CONCATENATE(E9,F9," ",D9) -> 9G1 Aşçılık | J9: =LEFT(I9,3) -> 9G1
A10: 55060660558 | B10: Merve RENÇBER | C10: Mesleki Eğitim + Diploma | D10: Aşçılık | E10: 9 | F10: G1 | G10: =RIGHT(A10,5) -> 60558 | H10: =B10 -> Merve RENÇBER | I10: =CONCATENATE(E10,F10," ",D10) -> 9G1 Aşçılık | J10: =LEFT(I10,3) -> 9G1
A11: 19979517570 | B11: Nisanur SUSUR | C11: Mesleki Eğitim + Diploma | D11: Aşçılık | E11: 9 | F11: G1 | G11: =RIGHT(A11,5) -> 17570 | H11: =B11 -> Nisanur SUSUR | I11: =CONCATENATE(E11,F11," ",D11) -> 9G1 Aşçılık | J11: =LEFT(I11,3) -> 9G1
A12: 49336599468 | B12: Ömer ÖZBEK | C12: Mesleki Eğitim + Diploma | D12: Aşçılık | E12: 9 | F12: G1 | G12: =RIGHT(A12,5) -> 99468 | H12: =B12 -> Ömer ÖZBEK | I12: =CONCATENATE(E12,F12," ",D12) -> 9G1 Aşçılık | J12: =LEFT(I12,3) -> 9G1
A13: 16925619616 | B13: Selman Musab YEŞİL | C13: Mesleki Eğitim + Diploma | D13: Aşçılık | E13: 9 | F13: G1 | G13: =RIGHT(A13,5) -> 19616 | H13: =B13 -> Selman Musab YEŞİL | I13: =CONCATENATE(E13,F13," ",D13) -> 9G1 Aşçılık | J13: =LEFT(I13,3) -> 9G1
A14: 34022049600 | B14: Enes BİLİBEY | C14: Mesleki Eğitim + Diploma | D14: Bilgisayar Teknik Servisi | E14: 9 | F14: A2 | G14: =RIGHT(A14,5) -> 49600 | H14: =B14 -> Enes BİLİBEY | I14: =CONCATENATE(E14,F14," ",D14) -> 9A2 Bilgisayar Teknik Servisi | J14: =LEFT(I14,3) -> 9A2
A15: 54121379552 | B15: Yiğit Efe SEVİM | C15: Mesleki Eğitim + Diploma | D15: Bilgisayar Teknik Servisi | E15: 9 | F15: A2 | G15: =RIGHT(A15,5) -> 79552 | H15: =B15 -> Yiğit Efe SEVİM | I15: =CONCATENATE(E15,F15," ",D15) -> 9A2 Bilgisayar Teknik Servisi | J15: =LEFT(I15,3) -> 9A2
... A34: 12203095394 | B34: Erdem DEMİRBÜKEN | C34: Mesleki Eğitim + Diploma | D34: Bobinaj | E34: 9 | F34: D | G34: =RIGHT(A34,5) -> 95394 | H34: =B34 -> Erdem DEMİRBÜKEN | I34: =CONCATENATE(E34,F34," ",D34) -> 9D Bobinaj | J34: =LEFT(I34,3) -> 9D
A35: 40589016238 | B35: Aleyna TERZİ | C35: Mesleki Eğitim + Diploma | D35: Cilt Bakımı Ve Makyaj | E35: 9 | G35: =RIGHT(A35,5) -> 16238 | H35: =B35 -> Aleyna TERZİ | I35: =CONCATENATE(E35,F35," ",D35) -> 9 Cilt Bakımı Ve Makyaj | J35: =LEFT(I35,3) -> 9 C
A36: 51217625784 | B36: Esma DEMİR | C36: Mesleki Eğitim + Diploma | D36: Cilt Bakımı Ve Makyaj | E36: 9 | F36: G | G36: =RIGHT(A36,5) -> 25784 | H36: =B36 -> Esma DEMİR | I36: =CONCATENATE(E36,F36," ",D36) -> 9G Cilt Bakımı Ve Makyaj | J36: =LEFT(I36,3) -> 9G
A37: 36112979828 | B37: Yiğithan KARAASLAN | C37: Mesleki Eğitim + Diploma | D37: Dizel Motorları Yakıt Pompası Ve Enjektör Ayarcılığı | E37: 9 | F37: B | G37: =RIGHT(A37,5) -> 79828 | H37: =B37 -> Yiğithan KARAASLAN | I37: =CONCATENATE(E37,F37," ",D37) -> 9B Dizel Motorları Yakıt Pompası Ve Enjektör Ayarcılığı | J37: =LEFT(I37,3) -> 9B
A38: 30305173642 | B38: Ayaz BULUT | C38: Mesleki Eğitim + Diploma | D38: Elektrik Tesisatları Ve Pano Montörlüğü | E38: 9 | F38: D | G38: =RIGHT(A38,5) -> 73642 | H38: =B38 -> Ayaz BULUT | I38: =CONCATENATE(E38,F38," ",D38) -> 9D Elektrik Tesisatları Ve Pano Montörlüğü | J38: =LEFT(I38,3) -> 9D
A39: 60790157308 | B39: Bedirhan Eren BÜLBÜL | C39: Mesleki Eğitim + Diploma | D39: Elektrik Tesisatları Ve Pano Montörlüğü | E39: 9 | F39: D | G39: =RIGHT(A39,5) -> 57308 | H39: =B39 -> Bedirhan Eren BÜLBÜL | I39: =CONCATENATE(E39,F39," ",D39) -> 9D Elektrik Tesisatları Ve Pano Montörlüğü | J39: =LEFT(I39,3) -> 9D
A40: 19442536138 | B40: Berat Can PEKMEZCİ | C40: Mesleki Eğitim + Diploma | D40: Elektrik Tesisatları Ve Pano Montörlüğü | E40: 9 | F40: D | G40: =RIGHT(A40,5) -> 36138 | H40: =B40 -> Berat Can PEKMEZCİ | I40: =CONCATENATE(E40,F40," ",D40) -> 9D Elektrik Tesisatları Ve Pano Montörlüğü | J40: =LEFT(I40,3) -> 9D
A41: 53365537186 | B41: Doğukan KEMİKSİZ | C41: Mesleki Eğitim + Diploma | D41: Elektrik Tesisatları Ve Pano Montörlüğü | E41: 9 | F41: D | G41: =RIGHT(A41,5) -> 37186 | H41: =B41 -> Doğukan KEMİKSİZ | I41: =CONCATENATE(E41,F41," ",D41) -> 9D Elektrik Tesisatları Ve Pano Montörlüğü | J41: =LEFT(I41,3) -> 9D
A42: 40657828190 | B42: Efe Can KAYA | C42: Mesleki Eğitim + Diploma | D42: Elektrik Tesisatları Ve Pano Montörlüğü | E42: 9 | F42: D | G42: =RIGHT(A42,5) -> 28190 | H42: =B42 -> Efe Can KAYA | I42: =CONCATENATE(E42,F42," ",D42) -> 9D Elektrik Tesisatları Ve Pano Montörlüğü | J42: =LEFT(I42,3) -> 9D
A43: 43954719192 | B43: Efe ÖZDİNÇ | C43: Mesleki Eğitim + Diploma | D43: Elektrik Tesisatları Ve Pano Montörlüğü | E43: 9 | F43: D | G43: =RIGHT(A43,5) -> 19192 | H43: =B43 -> Efe ÖZDİNÇ | I43: =CONCATENATE(E43,F43," ",D43) -> 9D Elektrik Tesisatları Ve Pano Montörlüğü | J43: =LEFT(I43,3) -> 9D
A44: 61492133706 | B44: Enes TEKE | C44: Mesleki Eğitim + Diploma | D44: Elektrik Tesisatları Ve Pano Montörlüğü | E44: 9 | F44: D | G44: =RIGHT(A44,5) -> 33706 | H44: =B44 -> Enes TEKE | I44: =CONCATENATE(E44,F44," ",D44) -> 9D Elektrik Tesisatları Ve Pano Montörlüğü | J44: =LEFT(I44,3) -> 9D
A45: 49885521170 | B45: İsmail EREN | C45: Mesleki Eğitim + Diploma | D45: Elektrik Tesisatları Ve Pano Montörlüğü | E45: 9 | F45: D | G45: =RIGHT(A45,5) -> 21170 | H45: =B45 -> İsmail EREN | I45: =CONCATENATE(E45,F45," ",D45) -> 9D Elektrik Tesisatları Ve Pano Montörlüğü | J45: =LEFT(I45,3) -> 9D
A46: 40990879118 | B46: Melik Özkan FİDAN | C46: Mesleki Eğitim + Diploma | D46: Elektrik Tesisatları Ve Pano Montörlüğü | E46: 9 | F46: D | G46: =RIGHT(A46,5) -> 79118 | H46: =B46 -> Melik Özkan FİDAN | I46: =CONCATENATE(E46,F46," ",D46) -> 9D Elektrik Tesisatları Ve Pano Montörlüğü | J46: =LEFT(I46,3) -> 9D
A47: 18512566778 | B47: Mert Doruk DEMİR | C47: Mesleki Eğitim + Diploma | D47: Elektrik Tesisatları Ve Pano Montörlüğü | E47: 9 | F47: D | G47: =RIGHT(A47,5) -> 66778 | H47: =B47 -> Mert Doruk DEMİR | I47: =CONCATENATE(E47,F47," ",D47) -> 9D Elektrik Tesisatları Ve Pano Montörlüğü | J47: =LEFT(I47,3) -> 9D
... A53: 28778224886 | B53: Tutku YILMAZLAR | C53: Mesleki Eğitim + Diploma | D53: Elektrik Tesisatları Ve Pano Montörlüğü | E53: 9 | F53: D | G53: =RIGHT(A53,5) -> 24886 | H53: =B53 -> Tutku YILMAZLAR | I53: =CONCATENATE(E53,F53," ",D53) -> 9D Elektrik Tesisatları Ve Pano Montörlüğü | J53: =LEFT(I53,3) -> 9D
A54: 60247175282 | B54: Yiğit Efe DİNLER | C54: Mesleki Eğitim + Diploma | D54: Elektrik Tesisatları Ve Pano Montörlüğü | E54: 9 | G54: =RIGHT(A54,5) -> 75282 | H54: =B54 -> Yiğit Efe DİNLER | I54: =CONCATENATE(E54,F54," ",D54) -> 9 Elektrik Tesisatları Ve Pano Montörlüğü | J54: =LEFT(I54,3) -> 9 E
A55: 36664961944 | B55: Yusuf Eren GÜRCÜ | C55: Mesleki Eğitim + Diploma | D55: Elektrik Tesisatları Ve Pano Montörlüğü | E55: 9 | F55: D | G55: =RIGHT(A55,5) -> 61944 | H55: =B55 -> Yusuf Eren GÜRCÜ | I55: =CONCATENATE(E55,F55," ",D55) -> 9D Elektrik Tesisatları Ve Pano Montörlüğü | J55: =LEFT(I55,3) -> 9D
A56: 15158678742 | B56: Arda UZUN | C56: Mesleki Eğitim + Diploma | D56: Elektrikli Ev Aletleri Teknik Servisi | E56: 9 | F56: D | G56: =RIGHT(A56,5) -> 78742 | H56: =B56 -> Arda UZUN | I56: =CONCATENATE(E56,F56," ",D56) -> 9D Elektrikli Ev Aletleri Teknik Servisi | J56: =LEFT(I56,3) -> 9D
A57: 37609655584 | B57: Hasan Erdoğan DEMİR | C57: Mesleki Eğitim + Diploma | D57: Elektrikli Ev Aletleri Teknik Servisi | E57: 9 | F57: D | G57: =RIGHT(A57,5) -> 55584 | H57: =B57 -> Hasan Erdoğan DEMİR | I57: =CONCATENATE(E57,F57," ",D57) -> 9D Elektrikli Ev Aletleri Teknik Servisi | J57: =LEFT(I57,3) -> 9D
A58: 37487304130 | B58: Recep Emin GÜNEY | C58: Mesleki Eğitim + Diploma | D58: Elektrikli Ev Aletleri Teknik Servisi | E58: 9 | F58: D | G58: =RIGHT(A58,5) -> 04130 | H58: =B58 -> Recep Emin GÜNEY | I58: =CONCATENATE(E58,F58," ",D58) -> 9D Elektrikli Ev Aletleri Teknik Servisi | J58: =LEFT(I58,3) -> 9D
A59: 49957518008 | B59: Berat Muhammet ÖZCİRİT | C59: Mesleki Eğitim + Diploma | D59: Endüstriyel Bakım Onarım | E59: 9 | F59: D | G59: =RIGHT(A59,5) -> 18008 | H59: =B59 -> Berat Muhammet ÖZCİRİT | I59: =CONCATENATE(E59,F59," ",D59) -> 9D Endüstriyel Bakım Onarım | J59: =LEFT(I59,3) -> 9D
A60: 39139879188 | B60: Kayra Ege ÇOBANOĞLU | C60: Mesleki Eğitim + Diploma | D60: Endüstriyel Bakım Onarım | E60: 9 | F60: D | G60: =RIGHT(A60,5) -> 79188 | H60: =B60 -> Kayra Ege ÇOBANOĞLU | I60: =CONCATENATE(E60,F60," ",D60) -> 9D Endüstriyel Bakım Onarım | J60: =LEFT(I60,3) -> 9D
A61: 36431339372 | B61: Emircan FIRAT | C61: Mesleki Eğitim + Diploma | D61: Endüstriyel Kontrol | E61: 9 | F61: A3(KARMA) | G61: =RIGHT(A61,5) -> 39372 | H61: =B61 -> Emircan FIRAT | I61: =CONCATENATE(E61,F61," ",D61) -> 9A3(KARMA) Endüstriyel Kontrol | J61: =LEFT(I61,3) -> 9A3
A62: 48043582510 | B62: Ömer KARATEPE | C62: Mesleki Eğitim + Diploma | D62: Endüstriyel Kontrol | E62: 9 | F62: A3(KARMA) | G62: =RIGHT(A62,5) -> 82510 | H62: =B62 -> Ömer KARATEPE | I62: =CONCATENATE(E62,F62," ",D62) -> 9A3(KARMA) Endüstriyel Kontrol | J62: =LEFT(I62,3) -> 9A3
A63: 52051449178 | B63: Yunus Emre BETİ | C63: Mesleki Eğitim + Diploma | D63: Endüstriyel Kontrol | E63: 9 | F63: A3(KARMA) | G63: =RIGHT(A63,5) -> 49178 | H63: =B63 -> Yunus Emre BETİ | I63: =CONCATENATE(E63,F63," ",D63) -> 9A3(KARMA) Endüstriyel Kontrol | J63: =LEFT(I63,3) -> 9A3
A64: 46909620680 | B64: Abdulkadir ELİK | C64: Mesleki Eğitim + Diploma | D64: Erkek Kuaförlüğü | E64: 9 | F64: E | G64: =RIGHT(A64,5) -> 20680 | H64: =B64 -> Abdulkadir ELİK | I64: =CONCATENATE(E64,F64," ",D64) -> 9E Erkek Kuaförlüğü | J64: =LEFT(I64,3) -> 9E
...

Sheet Sayfa1
A1: tc_son5 | B1: ad_soyad | C1: sube
A2: 85610 | B2: Umut KAYA | C2: 9D Asansör Sistemleri | D2: 9D | E2: =IF(COUNTIF(Sayfa2!$A$2:$A$8,"*"&D2&"*")>0, Sayfa2!$A$1, IF(COUNTIF(Sayfa2!$B$2:$B$8, "*"&D2&"*")>0, Sayfa2!$B$1, IF(COUNTIF(Sayfa2!$C$2:$C$8, "*"&D2&"*")>0, Sayfa2!$C$1, IF(COUNTIF(Sayfa2!$D$2:$D$8,"*"&D2&"*")>0, Sayfa2!$D$1, IF(COUNTIF(Sayfa2!$E$2:$E$8, "*"&D2&"*")>0, Sayfa2!$E$1, "Bulunamadı"))))) -> PERŞEMBE
A3: 87170 | B3: Ahmet Emin KAYA | C3: 9G1 Aşçılık | D3: 9G1 | E3: =IF(COUNTIF(Sayfa2!$A$2:$A$8,"*"&D3&"*")>0, Sayfa2!$A$1, IF(COUNTIF(Sayfa2!$B$2:$B$8, "*"&D3&"*")>0, Sayfa2!$B$1, IF(COUNTIF(Sayfa2!$C$2:$C$8, "*"&D3&"*")>0, Sayfa2!$C$1, IF(COUNTIF(Sayfa2!$D$2:$D$8,"*"&D3&"*")>0, Sayfa2!$D$1, IF(COUNTIF(Sayfa2!$E$2:$E$8, "*"&D3&"*")>0, Sayfa2!$E$1, "Bulunamadı"))))) -> Bulunamadı
A4: 19092 | B4: Bahruz ALIZADA | C4: 9G1 Aşçılık | D4: 9G1 | E4: =IF(COUNTIF(Sayfa2!$A$2:$A$8,"*"&D4&"*")>0, Sayfa2!$A$1, IF(COUNTIF(Sayfa2!$B$2:$B$8, "*"&D4&"*")>0, Sayfa2!$B$1, IF(COUNTIF(Sayfa2!$C$2:$C$8, "*"&D4&"*")>0, Sayfa2!$C$1, IF(COUNTIF(Sayfa2!$D$2:$D$8,"*"&D4&"*")>0, Sayfa2!$D$1, IF(COUNTIF(Sayfa2!$E$2:$E$8, "*"&D4&"*")>0, Sayfa2!$E$1, "Bulunamadı"))))) -> Bulunamadı
A5: 52934 | B5: Elifnur ŞENGÜL | C5: 9G1 Aşçılık | D5: 9G1 | E5: =IF(COUNTIF(Sayfa2!$A$2:$A$8,"*"&D5&"*")>0, Sayfa2!$A$1, IF(COUNTIF(Sayfa2!$B$2:$B$8, "*"&D5&"*")>0, Sayfa2!$B$1, IF(COUNTIF(Sayfa2!$C$2:$C$8, "*"&D5&"*")>0, Sayfa2!$C$1, IF(COUNTIF(Sayfa2!$D$2:$D$8,"*"&D5&"*")>0, Sayfa2!$D$1, IF(COUNTIF(Sayfa2!$E$2:$E$8, "*"&D5&"*")>0, Sayfa2!$E$1, "Bulunamadı"))))) -> Bulunamadı
A6: 75728 | B6: Gül Deniz BİLECEN | C6: 9G1 Aşçılık | D6: 9G1 | E6: =IF(COUNTIF(Sayfa2!$A$2:$A$8,"*"&D6&"*")>0, Sayfa2!$A$1, IF(COUNTIF(Sayfa2!$B$2:$B$8, "*"&D6&"*")>0, Sayfa2!$B$1, IF(COUNTIF(Sayfa2!$C$2:$C$8, "*"&D6&"*")>0, Sayfa2!$C$1, IF(COUNTIF(Sayfa2!$D$2:$D$8,"*"&D6&"*")>0, Sayfa2!$D$1, IF(COUNTIF(Sayfa2!$E$2:$E$8, "*"&D6&"*")>0, Sayfa2!$E$1, "Bulunamadı"))))) -> Bulunamadı
A7: 44094 | B7: Levent Eymen BAŞKÖYLÜ | C7: 9G1 Aşçılık | D7: 9G1 | E7: =IF(COUNTIF(Sayfa2!$A$2:$A$8,"*"&D7&"*")>0, Sayfa2!$A$1, IF(COUNTIF(Sayfa2!$B$2:$B$8, "*"&D7&"*")>0, Sayfa2!$B$1, IF(COUNTIF(Sayfa2!$C$2:$C$8, "*"&D7&"*")>0, Sayfa2!$C$1, IF(COUNTIF(Sayfa2!$D$2:$D$8,"*"&D7&"*")>0, Sayfa2!$D$1, IF(COUNTIF(Sayfa2!$E$2:$E$8, "*"&D7&"*")>0, Sayfa2!$E$1, "Bulunamadı"))))) -> Bulunamadı
A8: 60558 | B8: Merve RENÇBER | C8: 9G1 Aşçılık | D8: 9G1 | E8: =IF(COUNTIF(Sayfa2!$A$2:$A$8,"*"&D8&"*")>0, Sayfa2!$A$1, IF(COUNTIF(Sayfa2!$B$2:$B$8, "*"&D8&"*")>0, Sayfa2!$B$1, IF(COUNTIF(Sayfa2!$C$2:$C$8, "*"&D8&"*")>0, Sayfa2!$C$1, IF(COUNTIF(Sayfa2!$D$2:$D$8,"*"&D8&"*")>0, Sayfa2!$D$1, IF(COUNTIF(Sayfa2!$E$2:$E$8, "*"&D8&"*")>0, Sayfa2!$E$1, "Bulunamadı"))))) -> Bulunamadı
A9: 17570 | B9: Nisanur SUSUR | C9: 9G1 Aşçılık | D9: 9G1 | E9: =IF(COUNTIF(Sayfa2!$A$2:$A$8,"*"&D9&"*")>0, Sayfa2!$A$1, IF(COUNTIF(Sayfa2!$B$2:$B$8, "*"&D9&"*")>0, Sayfa2!$B$1, IF(COUNTIF(Sayfa2!$C$2:$C$8, "*"&D9&"*")>0, Sayfa2!$C$1, IF(COUNTIF(Sayfa2!$D$2:$D$8,"*"&D9&"*")>0, Sayfa2!$D$1, IF(COUNTIF(Sayfa2!$E$2:$E$8, "*"&D9&"*")>0, Sayfa2!$E$1, "Bulunamadı"))))) -> Bulunamadı
A10: 99468 | B10: Ömer ÖZBEK | C10: 9G1 Aşçılık | D10: 9G1 | E10: =IF(COUNTIF(Sayfa2!$A$2:$A$8,"*"&D10&"*")>0, Sayfa2!$A$1, IF(COUNTIF(Sayfa2!$B$2:$B$8, "*"&D10&"*")>0, Sayfa2!$B$1, IF(COUNTIF(Sayfa2!$C$2:$C$8, "*"&D10&"*")>0, Sayfa2!$C$1, IF(COUNTIF(Sayfa2!$D$2:$D$8,"*"&D10&"*")>0, Sayfa2!$D$1, IF(COUNTIF(Sayfa2!$E$2:$E$8, "*"&D10&"*")>0, Sayfa2!$E$1, "Bulunamadı"))))) -> Bulunamadı
A11: 19616 | B11: Selman Musab YEŞİL | C11: 9G1 Aşçılık | D11: 9G1 | E11: =IF(COUNTIF(Sayfa2!$A$2:$A$8,"*"&D11&"*")>0, Sayfa2!$A$1, IF(COUNTIF(Sayfa2!$B$2:$B$8, "*"&D11&"*")>0, Sayfa2!$B$1, IF(COUNTIF(Sayfa2!$C$2:$C$8, "*"&D11&"*")>0, Sayfa2!$C$1, IF(COUNTIF(Sayfa2!$D$2:$D$8,"*"&D11&"*")>0, Sayfa2!$D$1, IF(COUNTIF(Sayfa2!$E$2:$E$8, "*"&D11&"*")>0, Sayfa2!$E$1, "Bulunamadı"))))) -> Bulunamadı
A12: 49600 | B12: Enes BİLİBEY | C12: 9A2 Bilgisayar Teknik Servisi | D12: 9A2 | E12: =IF(COUNTIF(Sayfa2!$A$2:$A$8,"*"&D12&"*")>0, Sayfa2!$A$1, IF(COUNTIF(Sayfa2!$B$2:$B$8, "*"&D12&"*")>0, Sayfa2!$B$1, IF(COUNTIF(Sayfa2!$C$2:$C$8, "*"&D12&"*")>0, Sayfa2!$C$1, IF(COUNTIF(Sayfa2!$D$2:$D$8,"*"&D12&"*")>0, Sayfa2!$D$1, IF(COUNTIF(Sayfa2!$E$2:$E$8, "*"&D12&"*")>0, Sayfa2!$E$1, "Bulunamadı"))))) -> PAZARTESİ
A13: 79552 | B13: Yiğit Efe SEVİM | C13: 9A2 Bilgisayar Teknik Servisi | D13: 9A2 | E13: =IF(COUNTIF(Sayfa2!$A$2:$A$8,"*"&D13&"*")>0, Sayfa2!$A$1, IF(COUNTIF(Sayfa2!$B$2:$B$8, "*"&D13&"*")>0, Sayfa2!$B$1, IF(COUNTIF(Sayfa2!$C$2:$C$8, "*"&D13&"*")>0, Sayfa2!$C$1, IF(COUNTIF(Sayfa2!$D$2:$D$8,"*"&D13&"*")>0, Sayfa2!$D$1, IF(COUNTIF(Sayfa2!$E$2:$E$8, "*"&D13&"*")>0, Sayfa2!$E$1, "Bulunamadı"))))) -> PAZARTESİ
... A1363: 09708 | B1363: Mücahit BAYKAN | C1363: 12B1 Sac İşleri | D1363: 12B | E1363: =IF(COUNTIF(Sayfa2!$A$2:$A$8,"*"&D1363&"*")>0, Sayfa2!$A$1, IF(COUNTIF(Sayfa2!$B$2:$B$8, "*"&D1363&"*")>0, Sayfa2!$B$1, IF(COUNTIF(Sayfa2!$C$2:$C$8, "*"&D1363&"*")>0, Sayfa2!$C$1, IF(COUNTIF(Sayfa2!$D$2:$D$8,"*"&D1363&"*")>0, Sayfa2!$D$1, IF(COUNTIF(Sayfa2!$E$2:$E$8, "*"&D1363&"*")>0, Sayfa2!$E$1, "Bulunamadı"))))) -> PERŞEMBE

Sheet Sayfa2
A1: PAZARTESİ | B1: SALI | C1: ÇARŞAMBA | D1: PERŞEMBE | E1: CUMA
A2: 9A19A29A39A4 | B2: 9B9B19B29B39B4 | C2: 9C19C29C39C4 | D2: 9D19D29D39D4 | E2: 10A
A3: 10B | B3: 10C | C3: 10D | D3: 10E | E3: 10F
A4: 10G | B4: 10H | C4: 10İ | D4: 10K | E4: 10L
A5: 10M | B5: 11B | C5: 11C | D5: 11D | E5: 11E
A6: 11A | B6: 11F | C6: 11G | D6: 11H | E6: 11İ
A7: 11K | B7: 12C | C7: 12A | D7: 12B | E7: 12D
A8: 12E | B8: 12F | C8: 9F19F29F39F4 | E8: 9E19E29E39E4
